Workbook

Sheet Problem Statement
C3: Stratascratch Project: Hospitalization Hypothesis Testing | V3: https://platform.stratascratch.com/data-projects/hospitalization-hypothesis-testing
D5: This data project has been used as a take-home assignment in the recruitment process for the data science positions at Apollo Hospitals.
D6: Apollo Hospitals was established in 1983, renowned as the architect of modern healthcare in India. As the nation's first corporate hospital, Apollo Hospitals is acclaimed for pioneering the private healthcare revolution in the country.
D9: Assignment
E10: As a data scientist working at Apollo, the ultimate goal is to tease out meaningful and actionable insights from Patient-level collected data. You can help Apollo hospitals to be more efficient, influence diagnostic and treatment processes, and to map the spread of a pandemic.
E12: One of the best examples of data scientists making a meaningful difference at a global level is in the response to the COVID-19 pandemic, where they have improved information collection, provided ongoing and accurate estimates of infection spread and health system demand, and assessed the effectiveness of government policies.
D16: The company wants to know:
E17: Which variables are significant in predicting the reason for hospitalization for different regions;
E18: How well some variables like viral load, smoking, and severity level describe the hospitalization charges;
D20: Data Description
E21: The file apollo_data.csv contains anonymized data of COVID-19 hospital patients and contains the following variables:
E22: age - an integer indicating the age of the primary beneficiary (excluding those above 64 years, since they are generally covered by the government)
E23: sex - the policy holder's gender, either male or female
E24: smoker - 'yes' or 'no' depending on whether the insured regularly smokes tobacco
E25: region - beneficiary's place of residence in Delhi, divided into four geographic regions - northeast, southeast, southwest, or northwest
E26: viral load - the amount of virus in an infected person's blood
E27: severity level - an integer indicating how severe the patient is
E28: hospitalization charges - individual medical costs billed to health insurance
D30: Practicalities
E31: Analyze the provided data and provide insights to the best of your abilities. Use statistical tests to support your claims. Include the relevant tables/graphs/visualization to explain what you have learned. Make sure that the solution reflects your entire thought process including the preparation of data - it is more important how the code is structured rather than just the final result or plot.

Sheet Executive Summary
C3: PROJECT: DETERMINANTS OF HOSPITALIZATION CHARGES & PATIENT PROFILES | T3: https://platform.stratascratch.com/data-projects/hospitalization-hypothesis-testing
D5: 1. PROJECT OVERVIEW
E6: Objective:
F7: To analyze 1,338 patient records to identify significant drivers of hospitalization charges and evaluate demographic patterns for Apollo Hospitals.
E10: Scope:
F11: Analysis of key variables including Smoking Status, Viral Load, Severity Level, and Region.
E13: Methodology:
F14: Descriptive Statistics, Welch’s T-Test, Pearson Correlation, ANOVA Single Factor, and Chi-Square Test of Independence.
D17: 2. KEY FINDINGS & INSIGHTS
E18: A. The "Smoker" Effect (Financial Impact)
F19: Insight: Smoking is the single largest predictor of hospitalization costs.
F20: Data: Smokers average $80,125 in charges vs. $21,085 for non-smokers.
F21: Statistical Evidence: The difference is highly significant ($P \approx 0$, Welch’s T-Test).
F22: Business Implication: Risk adjustment models and insurance premiums must weigh smoking status as the primary cost multiplier (~4x increase).
E25: B. Viral Load & Clinical Metrics
F26: Insight: Viral load is a weak predictor of financial cost.
F27: Data: Pearson Correlation Coefficient ($r$) is 0.198.
F28: Business Implication: High viral load does not automatically equate to high resource consumption or billing; operational planning should focus on other severity metrics.
E31: C. Severity Level Trends
F32: Insight: Severity impacts costs, but the relationship is non-linear.
F33: Data: Statistically significant difference found among groups (ANOVA, $P = 0.0058$). However, the highest severity levels (4 & 5) showed lower average costs than mid-tier severity.
F35: Note: This anomaly is likely due to low sample size in high-severity tiers (n=25 and n=18) and requires further data collection for validation.
E38: D. Regional Demographics
F39: Insight: Smoking habits are relatively consistent across all four regions (SW, SE, NW, NE).
F40: Statistical Evidence: Chi-Square test ($P = 0.057$) indicates no statistically significant dependence between Region and Smoking Status at the 5% level.
F42: Business Implication: Regional-specific marketing or risk strategies regarding smoking may yield diminishing returns; a unified national strategy is recommended.
D45: 3. Recommendations
E46: Pricing Strategy: Implement tiered pricing or higher premiums specifically for smokers given the 400% cost variance.
E48: Predictive Modeling: Future machine learning models should prioritize Lifestyle (Smoking) and Demographics over Viral Load for cost prediction.
E50: Data Quality: Increase data collection efforts for "Severity Level 4 & 5" patients to correct potential sample bias in cost analysis.

Sheet Recoomendations
B3: Summary of Key Insights for Apollo Hospitals:
C5: Smoker vs. Charges (T-Test): Highly Significant (P approx 0). Smoking is the dominant predictor of high costs, with smokers costing approx 4 times more than non-smokers.
C7: Viral Load vs. Charges (Correlation): Very Weak relationship (r approx 0.198). Viral Load is not a useful cost predictor on its own.
C9: Severity vs. Charges (ANOVA): Significant (P approx 0.0058). Severity level as a group is a factor, but the pattern is non-linear (Severity 5 had the lowest average cost), suggesting confounding variables are at play.
C11: Region vs. Smoker (Chi-Square): Not Statistically Significant at the 5% level (P approx 0.057). While the Southeast region had the highest count of smokers (91 observed vs. 74 expected), the difference is not strong enough to confidently say that smoking rates are dependent on the region.

Sheet Univariate Analysis
B2: Univariate Analysis
C4: Total Records: | D4: 1338
F6: Equal Split | I6: Imbalanced | L6: Normal Distribution | O6: Right Skewed
C7: Age | D7: # Records | F7: Sex | G7: # Records | I7: Smoker | J7: # Records | L7: Virality | M7: # Records | O7: Hospitalization Charges Less Than | P7: # Records
C8: 18 | D8: =COUNTIFS('Raw Data'!$D$5:$D$1342,'Univariate Analysis'!C8) -> 69 | F8: female | G8: =COUNTIFS('Raw Data'!$E$5:$E$1342,'Univariate Analysis'!F8) -> 662 | I8: yes | J8: =COUNTIFS('Raw Data'!$F$5:$F$1342,'Univariate Analysis'!I8) -> 274 | L8: 5 | M8: =COUNTIFS('Raw Data'!$H$5:$H$1342,"<="&('Univariate Analysis'!L8+1)) -> 15 | O8: 10000 | P8: =COUNTIFS('Raw Data'!$J$5:$J$1342,"<="&('Univariate Analysis'!O8+1)) -> 269
C9: 19 | D9: =COUNTIFS('Raw Data'!$D$5:$D$1342,'Univariate Analysis'!C9) -> 68 | F9: male | G9: =COUNTIFS('Raw Data'!$E$5:$E$1342,'Univariate Analysis'!F9) -> 676 | I9: no | J9: =COUNTIFS('Raw Data'!$F$5:$F$1342,'Univariate Analysis'!I9) -> 1064 | L9: 6 | M9: =COUNTIFS('Raw Data'!$H$5:$H$1342,"<="&('Univariate Analysis'!L9+1), 'Raw Data'!$H$5:$H$1342,">"&(L8+1)) -> 50 | O9: 20000 | P9: =COUNTIFS('Raw Data'!$J$5:$J$1342,"<="&('Univariate Analysis'!O9+1), 'Raw Data'!$J$5:$J$1342,">"&(O8+1)) -> 301
C10: 20 | D10: =COUNTIFS('Raw Data'!$D$5:$D$1342,'Univariate Analysis'!C10) -> 29 | L10: 7 | M10: =COUNTIFS('Raw Data'!$H$5:$H$1342,"<="&('Univariate Analysis'!L10+1), 'Raw Data'!$H$5:$H$1342,">"&(L9+1)) -> 123 | O10: 30000 | P10: =COUNTIFS('Raw Data'!$J$5:$J$1342,"<="&('Univariate Analysis'!O10+1), 'Raw Data'!$J$5:$J$1342,">"&(O9+1)) -> 276
C11: 21 | D11: =COUNTIFS('Raw Data'!$D$5:$D$1342,'Univariate Analysis'!C11) -> 28 | F11: Equal Split | L11: 8 | M11: =COUNTIFS('Raw Data'!$H$5:$H$1342,"<="&('Univariate Analysis'!L11+1), 'Raw Data'!$H$5:$H$1342,">"&(L10+1)) -> 197 | O11: 40000 | P11: =COUNTIFS('Raw Data'!$J$5:$J$1342,"<="&('Univariate Analysis'!O11+1), 'Raw Data'!$J$5:$J$1342,">"&(O10+1)) -> 146
C12: 22 | D12: =COUNTIFS('Raw Data'!$D$5:$D$1342,'Univariate Analysis'!C12) -> 28 | F12: Region | G12: # Records | I12: Severity | J12: # Records | L12: 9 | M12: =COUNTIFS('Raw Data'!$H$5:$H$1342,"<="&('Univariate Analysis'!L12+1), 'Raw Data'!$H$5:$H$1342,">"&(L11+1)) -> 248 | O12: 50000 | P12: =COUNTIFS('Raw Data'!$J$5:$J$1342,"<="&('Univariate Analysis'!O12+1), 'Raw Data'!$J$5:$J$1342,">"&(O11+1)) -> 73
C13: 23 | D13: =COUNTIFS('Raw Data'!$D$5:$D$1342,'Univariate Analysis'!C13) -> 28 | F13: southwest | G13: =COUNTIFS('Raw Data'!$G$5:$G$1342,'Univariate Analysis'!F13) -> 325 | I13: 0 | J13: =COUNTIFS('Raw Data'!$I$5:$I$1342,'Univariate Analysis'!I13) -> 574 | L13: 10 | M13: =COUNTIFS('Raw Data'!$H$5:$H$1342,"<="&('Univariate Analysis'!L13+1), 'Raw Data'!$H$5:$H$1342,">"&(L12+1)) -> 249 | O13: 60000 | P13: =COUNTIFS('Raw Data'!$J$5:$J$1342,"<="&('Univariate Analysis'!O13+1), 'Raw Data'!$J$5:$J$1342,">"&(O12+1)) -> 56
C14: 24 | D14: =COUNTIFS('Raw Data'!$D$5:$D$1342,'Univariate Analysis'!C14) -> 28 | F14: southeast | G14: =COUNTIFS('Raw Data'!$G$5:$G$1342,'Univariate Analysis'!F14) -> 364 | I14: 1 | J14: =COUNTIFS('Raw Data'!$I$5:$I$1342,'Univariate Analysis'!I14) -> 324 | L14: 11 | M14: =COUNTIFS('Raw Data'!$H$5:$H$1342,"<="&('Univariate Analysis'!L14+1), 'Raw Data'!$H$5:$H$1342,">"&(L13+1)) -> 200 | O14: 70000 | P14: =COUNTIFS('Raw Data'!$J$5:$J$1342,"<="&('Univariate Analysis'!O14+1), 'Raw Data'!$J$5:$J$1342,">"&(O13+1)) -> 43
C15: 25 | D15: =COUNTIFS('Raw Data'!$D$5:$D$1342,'Univariate Analysis'!C15) -> 28 | F15: northwest | G15: =COUNTIFS('Raw Data'!$G$5:$G$1342,'Univariate Analysis'!F15) -> 325 | I15: 2 | J15: =COUNTIFS('Raw Data'!$I$5:$I$1342,'Univariate Analysis'!I15) -> 240 | L15: 12 | M15: =COUNTIFS('Raw Data'!$H$5:$H$1342,"<="&('Univariate Analysis'!L15+1), 'Raw Data'!$H$5:$H$1342,">"&(L14+1)) -> 130 | O15: 80000 | P15: =COUNTIFS('Raw Data'!$J$5:$J$1342,"<="&('Univariate Analysis'!O15+1), 'Raw Data'!$J$5:$J$1342,">"&(O14+1)) -> 19
C16: 26 | D16: =COUNTIFS('Raw Data'!$D$5:$D$1342,'Univariate Analysis'!C16) -> 28 | F16: northeast | G16: =COUNTIFS('Raw Data'!$G$5:$G$1342,'Univariate Analysis'!F16) -> 324 | I16: 3 | J16: =COUNTIFS('Raw Data'!$I$5:$I$1342,'Univariate Analysis'!I16) -> 157 | L16: 13 | M16: =COUNTIFS('Raw Data'!$H$5:$H$1342,"<="&('Univariate Analysis'!L16+1), 'Raw Data'!$H$5:$H$1342,">"&(L15+1)) -> 77 | O16: 90000 | P16: =COUNTIFS('Raw Data'!$J$5:$J$1342,"<="&('Univariate Analysis'!O16+1), 'Raw Data'!$J$5:$J$1342,">"&(O15+1)) -> 28
C17: 27 | D17: =COUNTIFS('Raw Data'!$D$5:$D$1342,'Univariate Analysis'!C17) -> 28 | I17: 4 | J17: =COUNTIFS('Raw Data'!$I$5:$I$1342,'Univariate Analysis'!I17) -> 25 | L17: 14 | M17: =COUNTIFS('Raw Data'!$H$5:$H$1342,"<="&('Univariate Analysis'!L17+1), 'Raw Data'!$H$5:$H$1342,">"&(L16+1)) -> 29 | O17: 100000 | P17: =COUNTIFS('Raw Data'!$J$5:$J$1342,"<="&('Univariate Analysis'!O17+1), 'Raw Data'!$J$5:$J$1342,">"&(O16+1)) -> 48
C18: 28 | D18: =COUNTIFS('Raw Data'!$D$5:$D$1342,'Univariate Analysis'!C18) -> 28 | I18: 5 | J18: =COUNTIFS('Raw Data'!$I$5:$I$1342,'Univariate Analysis'!I18) -> 18 | L18: 15 | M18: =COUNTIFS('Raw Data'!$H$5:$H$1342,"<="&('Univariate Analysis'!L18+1), 'Raw Data'!$H$5:$H$1342,">"&(L17+1)) -> 15 | O18: 110000 | P18: =COUNTIFS('Raw Data'!$J$5:$J$1342,"<="&('Univariate Analysis'!O18+1), 'Raw Data'!$J$5:$J$1342,">"&(O17+1)) -> 34
C19: 29 | D19: =COUNTIFS('Raw Data'!$D$5:$D$1342,'Univariate Analysis'!C19) -> 27 | L19: 16 | M19: =COUNTIFS('Raw Data'!$H$5:$H$1342,"<="&('Univariate Analysis'!L19+1), 'Raw Data'!$H$5:$H$1342,">"&(L18+1)) -> 3 | O19: 120000 | P19: =COUNTIFS('Raw Data'!$J$5:$J$1342,"<="&('Univariate Analysis'!O19+1), 'Raw Data'!$J$5:$J$1342,">"&(O18+1)) -> 29
C20: 30 | D20: =COUNTIFS('Raw Data'!$D$5:$D$1342,'Univariate Analysis'!C20) -> 27 | L20: 17 | M20: =COUNTIFS('Raw Data'!$H$5:$H$1342,"<="&('Univariate Analysis'!L20+1), 'Raw Data'!$H$5:$H$1342,">"&(L19+1)) -> 2 | O20: 130000 | P20: =COUNTIFS('Raw Data'!$J$5:$J$1342,"<="&('Univariate Analysis'!O20+1), 'Raw Data'!$J$5:$J$1342,">"&(O19+1)) -> 10
C21: 31 | D21: =COUNTIFS('Raw Data'!$D$5:$D$1342,'Univariate Analysis'!C21) -> 27 | O21: 140000 | P21: =COUNTIFS('Raw Data'!$J$5:$J$1342,"<="&('Univariate Analysis'!O21+1), 'Raw Data'!$J$5:$J$1342,">"&(O20+1)) -> 2
C22: 32 | D22: =COUNTIFS('Raw Data'!$D$5:$D$1342,'Univariate Analysis'!C22) -> 26
C23: 33 | D23: =COUNTIFS('Raw Data'!$D$5:$D$1342,'Univariate Analysis'!C23) -> 26
C24: 34 | D24: =COUNTIFS('Raw Data'!$D$5:$D$1342,'Univariate Analysis'!C24) -> 26
C25: 35 | D25: =COUNTIFS('Raw Data'!$D$5:$D$1342,'Univariate Analysis'!C25) -> 25
C26: 36 | D26: =COUNTIFS('Raw Data'!$D$5:$D$1342,'Univariate Analysis'!C26) -> 25
C27: 37 | D27: =COUNTIFS('Raw Data'!$D$5:$D$1342,'Univariate Analysis'!C27) -> 25
C28: 38 | D28: =COUNTIFS('Raw Data'!$D$5:$D$1342,'Univariate Analysis'!C28) -> 25
C29: 39 | D29: =COUNTIFS('Raw Data'!$D$5:$D$1342,'Univariate Analysis'!C29) -> 25
C30: 40 | D30: =COUNTIFS('Raw Data'!$D$5:$D$1342,'Univariate Analysis'!C30) -> 27
C31: 41 | D31: =COUNTIFS('Raw Data'!$D$5:$D$1342,'Univariate Analysis'!C31) -> 27
C32: 42 | D32: =COUNTIFS('Raw Data'!$D$5:$D$1342,'Univariate Analysis'!C32) -> 27
C33: 43 | D33: =COUNTIFS('Raw Data'!$D$5:$D$1342,'Univariate Analysis'!C33) -> 27
... C54: 64 | D54: =COUNTIFS('Raw Data'!$D$5:$D$1342,'Univariate Analysis'!C54) -> 22

Sheet Hypothesis Testing - Smoking
B2: Hypothesis Testing - Smoking
C4: Let's pick the variable that usually has the highest impact on health costs: Smoking.
C6: To answer this statistically, we use Hypothesis Testing. This is a way of asking: "Is the difference in charges between smokers and non-smokers real, or did it just happen by random chance?"
C8: We define two hypotheses:
D9: Null Hypothesis (H_0): Smoking has no effect on hospitalization charges. (The average charge for smokers = average charge for non-smokers).
D10: Alternative Hypothesis (H_a): Smoking does affect hospitalization charges. (The averages are different).
E13: Smoker | F13: Average Hospitalization Charges | G13: Std Dev Hospitalization Charges
E14: Yes | F14: =AVERAGEIFS('Raw Data'!$J$5:$J$1342,'Raw Data'!$F$5:$F$1342,'Hypothesis Testing - Smoking'!E14) -> 80125.573 | G14: ='Raw Data'!N1 -> 28801.19
E15: No | F15: =AVERAGEIFS('Raw Data'!$J$5:$J$1342,'Raw Data'!$F$5:$F$1342,'Hypothesis Testing - Smoking'!E15) -> 21085.676 | G15: ='Raw Data'!M1 -> 14977.412
E18: t-Test: Two-Sample Assuming Unequal Variances
F20: Smoker | G20: Non-Smoker
E21: Mean | F21: 80125.573 | G21: 21085.676
E22: Variance | F22: 8.3254703e+08 | G22: 2.2453391e+08
E23: Observations | F23: 274 | G23: 1064
E24: Hypothesized Mean Difference | F24: 0
E25: df | F25: 312
E26: t Stat | F26: 32.751857
E27: P(T<=t) one-tail | F27: 2.7920875e-103
E28: t Critical one-tail | F28: 1.6497521
E29: P(T<=t) two-tail | F29: 5.5841749e-103
E30: t Critical two-tail | F30: 1.9675965
D32: Decision: Since the P-value is much, much less than alpha (0.05), we reject the Null Hypothesis H_0.
D33: Decision: Since the absolute value of the T-statistic (32.75) is greater than the Critical T Value (1.9676), we also reject the Null Hypothesis H_0.
C35: The Final Conclusion: The difference in hospitalization charges between smokers (approx $80,125 and non-smokers (approx $21,085) is statistically highly significant.
C37: Smoking is the most significant variable in determining the magnitude of hospitalization charges. A patient's smoking status is a powerful predictor for costs, with smokers costing the hospital (or insurer) nearly four times more on average. This insight is crucial for risk assessment and pricing strategies.

Sheet Correlation - Viral
B2: Correlation Analysis - Viral Load vs Hospitalization Charges
C5: Viral Load | D5: Hospitalization Charges
C6: 9.3 | D6: 42212 | G6: Now let's look at a different type of relationship: Viral Load and Hospitalization Charges. Since both are continuous (numerical) variables, the appropriate statistical tool is Correlation.
C7: 11.26 | D7: 4314
C8: 11 | D8: 11124 | H8: Column 1 | I8: Column 2
C9: 7.57 | D9: 54961 | G9: Column 1 | H9: 1
C10: 9.63 | D10: 9667 | G10: Column 2 | H10: 0.19838753 | I10: 1
C11: 8.58 | D11: 9392
C12: 11.15 | D12: 20601 | G12: =CORREL(C6:C1343,D6:D1343) -> 0.19838753
C13: 9.25 | D13: 18204
C14: 9.94 | D14: 16016 | G14: Direction: Since r is positive (0.198), there is a positive direction. This means that as Viral Load increases, Hospitalization Charges tend to slightly increase as well.
C15: 8.61 | D15: 72308 | G15: Strength: The value r 0.198 is classified as a very weak or bordering on weak positive relationship.
C16: 8.74 | D16: 6803
C17: 8.76 | D17: 69522 | G17: Insight for Apollo Hospitals: While there is a statistically detectable positive link between Viral Load and Charges, the relationship is very weak. This variable alone is not a strong predictor of high hospitalization costs. Compared to Smoking (r value would be very high, which you demonstrated with the t-test), Viral Load has minimal predictive power.
C18: 11.47 | D18: 4567
C19: 13.27 | D19: 27727
C20: 14.04 | D20: 99029
C21: 8.2 | D21: 4593
C22: 10.26 | D22: 26993
C23: 7.95 | D23: 5988
C24: 13.43 | D24: 26506
C25: 11.77 | D25: 92094
C26: 12 | D26: 33072
C27: 10.8 | D27: 10374
C28: 11.37 | D28: 2843
C29: 10.64 | D29: 94255
... C1343: 9.69 | D1343: 72853

Sheet ANOVA - Severity
B2: ANOVA - Indentifying Signals in Severity
B6: Std Dev | C6: =_xlfn.STDEV.P(C9:C582) -> 30032.043 | D6: =_xlfn.STDEV.P(D9:D332) -> 29513.439 | E6: =_xlfn.STDEV.P(E9:E248) -> 32161.21 | F6: =_xlfn.STDEV.P(F9:F165) -> 30728.809 | G6: =_xlfn.STDEV.P(G9:G33) -> 22386.457 | H6: =_xlfn.STDEV.P(H9:H26) -> 9252.7944 | K6: Severity | L6: Average | M6: Std Dev | O6: ANOVA tests the Null Hypothesis H_0: that the means of all groups are equal
B7: Average | C7: =AVERAGE(C9:C582) -> 30914.941 | D7: =AVERAGE(D9:D332) -> 31827.935 | E7: =AVERAGE(E9:E248) -> 37683.908 | F7: =AVERAGE(F9:F165) -> 38388.306 | G7: =AVERAGE(G9:G33) -> 34626.68 | H7: =AVERAGE(H9:H26) -> 21965 | K7: 0 | L7: 30914.941 | M7: 30032.043
B8: Severity | C8: 0 | D8: 1 | E8: 2 | F8: 3 | G8: 4 | H8: 5 | K8: 1 | L8: 31827.935 | M8: 29513.439
C9: 42212 | D9: 4314 | E9: 16016 | F9: 11124 | G9: 11262 | H9: 11719 | K9: 2 | L9: 37683.908 | M9: 32161.21
C10: 54961 | D10: 20601 | E10: 15510 | F10: 18204 | G10: 27584 | H10: 16999 | K10: 3 | L10: 38388.306 | M10: 30728.809
C11: 9667 | D11: 4593 | E11: 30672 | F11: 35003 | G11: 26018 | H11: 12077 | K11: 4 | L11: 34626.68 | M11: 22386.457
C12: 9392 | D12: 26993 | E12: 96778 | F12: 39030 | G12: 20407 | H12: 12700 | K12: 5 | L12: 21965 | M12: 9252.7944
C13: 72308 | D13: 10374 | E13: 12374 | F13: 20149 | G13: 28800 | H13: 24472
C14: 6803 | D14: 94255 | E14: 15784 | F14: 21516 | G14: 61679 | H14: 31481 | K14: Anova: Single Factor
C15: 69522 | D15: 6938 | E15: 8483 | F15: 44158 | G15: 27443 | H15: 28882
C16: 4567 | D16: 127986 | E16: 8950 | F16: 29354 | G16: 26842 | H16: 16666 | K16: SUMMARY
C17: 27727 | D17: 99436 | E17: 118741 | F17: 75462 | G17: 18781 | H17: 16634 | K17: Groups | L17: Count | M17: Sum | N17: Average | O17: Variance
C18: 99029 | D18: 15681 | E18: 34018 | F18: 30263 | G18: 44855 | H18: 25242 | K18: 0 | L18: 574 | M18: 17745176 | N18: 30914.941 | O18: 9.0349767e+08
C19: 5988 | D19: 15199 | E19: 85758 | F19: 77355 | G19: 100456 | H19: 22414 | K19: 1 | L19: 324 | M19: 10312251 | N19: 31827.935 | O19: 8.7373979e+08
C20: 26506 | D20: 96773 | E20: 14974 | F20: 28721 | G20: 32373 | H20: 21492 | K20: 2 | L20: 240 | M20: 9044138 | N20: 37683.908 | O20: 1.0386712e+09
C21: 92094 | D21: 58921 | E21: 35588 | F21: 25288 | G21: 35986 | H21: 12288 | K21: 3 | L21: 157 | M21: 6026964 | N21: 38388.306 | O21: 9.5031268e+08
C22: 33072 | D22: 58112 | E22: 19317 | F22: 68307 | G22: 42821 | H22: 47558 | K22: 4 | L22: 25 | M22: 865667 | N22: 34626.68 | O22: 5.2203485e+08
C23: 2843 | D23: 75417 | E23: 99591 | F23: 51865 | G23: 12195 | H23: 23056 | K23: 5 | L23: 18 | M23: 395370 | N23: 21965 | O23: 90650334
C24: 36130 | D24: 10334 | E24: 52746 | F24: 12846 | G24: 18110 | H24: 21456
C25: 88964 | D25: 15973 | E25: 14323 | F25: 101801 | G25: 91451 | H25: 14038
C26: 5495 | D26: 29867 | E26: 118228 | F26: 15836 | G26: 14272 | H26: 36196 | K26: ANOVA
C27: 34425 | D27: 9869 | E27: 9693 | F27: 49373 | G27: 28248 | K27: Source of Variation | L27: SS | M27: df | N27: MS | O27: F | P27: P-value | Q27: F crit
C28: 4064 | D28: 11103 | E28: 29703 | F28: 15322 | G28: 11403 | K28: Between Groups | L28: 1.4980772e+10 | M28: 5 | N28: 2.9961545e+09 | O28: 3.2969294 | P28: 0.0057855702 | Q28: 2.2208175
C29: 5756 | D29: 92913 | E29: 16716 | F29: 12070 | G29: 27538 | K29: Within Groups | L29: 1.2104832e+12 | M29: 1332 | N29: 9.0877118e+08
C30: 120433 | D30: 27355 | E30: 19351 | F30: 21346 | G30: 15148
C31: 7615 | D31: 9417 | E31: 81835 | F31: 10014 | G31: 39572 | K31: Total | L31: 1.225464e+12 | M31: 1337
C32: 51576 | D32: 12510 | E32: 15206 | F32: 109383 | G32: 53681
C33: 8892 | D33: 43901 | E33: 27909 | F33: 13314 | G33: 48742
C34: 31575 | D34: 5829 | E34: 68440 | F34: 13134 | K34: Decision: Since the P-value 0.00578 is less than alpha (0.05), we reject the Null Hypothesis (H_0).
C35: 5528 | D35: 27063 | E35: 47431 | F35: 29968 | K35: Decision: Since the F-statistic (3.297) is greater than the Critical F Value (2.221), we also reject the Null Hypothesis (H_0).
C36: 94356 | D36: 47769 | E36: 45395 | F36: 35003
C37: 36779 | D37: 98891 | E37: 12880 | F37: 17992
C38: 4358 | D38: 8726 | E38: 16140 | F38: 10652 | J38: Insight for Apollo Hospitals: While the overall trend is significant, the counter-intuitive drop in charges for Severity 4 and 5 (as noted in Step 7) suggests that the relationship is not purely linear. This variable is a significant factor in cost, but it interacts with other variables (like smoking, which we already saw is a dominant cost driver) and its effect is non-monotonic (doesn't just go up or down consistently).
C39: 14800 | D39: 24694 | E39: 22058 | F39: 32618
C40: 41444 | D40: 27399 | E40: 19329 | F40: 62175
C41: 28392 | D41: 4606 | E41: 9955 | F41: 51157
C42: 3831 | D42: 12813 | E42: 12307 | F42: 115378
C43: 6888 | D43: 17693 | E43: 21292 | F43: 36477
C44: 16428 | D44: 26126 | E44: 52460 | F44: 121373
...

Sheet Chi Square - Regions
B2: Chi Square - Regions
C4: Which variables are significant in predicting the reason for hospitalization for different regions.
C6: Region and Smoking
D7: H_0 (Null Hypothesis): Region and Smoker status are Independent (not related).
D8: H_a (Alternative Hypothesis): Region and Smoker status are Dependent (related).
D10: Region | E10: Count (No) | F10: Count (Yes) | G10: Row Total
D11: Northeast | E11: 257 | F11: 67 | G11: 324
D12: Northwest | E12: 267 | F12: 58 | G12: 325
D13: Southeast | E13: 273 | F13: 91 | G13: 364
D14: Southwest | E14: 267 | F14: 58 | G14: 325
D15: Col Total | E15: 1064 | F15: 274 | G15: 1338
D18: Region | E18: Observed (O) | F18: Expected (E) | G18: (O−E)2/E
D19: NE No | E19: 257 | F19: 257.65 | G19: 0.0016
D20: NE Yes | E20: 67 | F20: 66.35 | G20: 0.0063
D21: NW No | E21: 267 | F21: 258.45 | G21: 0.2878
D22: NW Yes | E22: 58 | F22: 66.55 | G22: 1.0963
D23: SE No | E23: 273 | F23: 289.58 | G23: 0.9416
D24: SE Yes | E24: 91 | F24: 74.42 | G24: 3.7915
D25: SW No | E25: 267 | F25: 258.45 | G25: 0.2878
D26: SW Yes | E26: 58 | F26: 66.55 | G26: 1.0963
D27: TOTAL | G27: 7.519
D29: Degrees of Freedom = 3
D30: P Value | E30: =_xlfn.CHISQ.DIST.RT(G27,3) -> 0.057072265
C32: Since the P-value 0.0570 is slightly greater than alpha (0.05), we fail to reject the Null Hypothesis H_0.

Sheet Raw Data
M1: =_xlfn.STDEV.P(M5:M1068) -> 14977.412 | N1: =_xlfn.STDEV.P(N5:N278) -> 28801.19
B2: Raw Data | M2: =AVERAGE(M5:M1068) -> 21085.676 | N2: =AVERAGE(N5:N278) -> 80125.573
M3: Non Smoker | N3: Smoker
C4: Record ID | D4: Age | E4: Sex | F4: Smoker | G4: Region | H4: Viral Load | I4: Severity Level | J4: Hospitalization Charges | M4: Hospitalization Charges | N4: Hospitalization Charges
C5: 0 | D5: 19 | E5: female | F5: yes | G5: southwest | H5: 9.3 | I5: 0 | J5: 42212 | M5: 4314 | N5: 42212
C6: 1 | D6: 18 | E6: male | F6: no | G6: southeast | H6: 11.26 | I6: 1 | J6: 4314 | M6: 11124 | N6: 69522
C7: 2 | D7: 28 | E7: male | F7: no | G7: southeast | H7: 11 | I7: 3 | J7: 11124 | M7: 54961 | N7: 99029
C8: 3 | D8: 33 | E8: male | F8: no | G8: northwest | H8: 7.57 | I8: 0 | J8: 54961 | M8: 9667 | N8: 92094
C9: 4 | D9: 32 | E9: male | F9: no | G9: northwest | H9: 9.63 | I9: 0 | J9: 9667 | M9: 9392 | N9: 94255
C10: 5 | D10: 31 | E10: female | F10: no | G10: southeast | H10: 8.58 | I10: 0 | J10: 9392 | M10: 20601 | N10: 96778
C11: 6 | D11: 46 | E11: female | F11: no | G11: southeast | H11: 11.15 | I11: 1 | J11: 20601 | M11: 18204 | N11: 88964
C12: 7 | D12: 37 | E12: female | F12: no | G12: northwest | H12: 9.25 | I12: 3 | J12: 18204 | M12: 16016 | N12: 127986
C13: 8 | D13: 37 | E13: male | F13: no | G13: northeast | H13: 9.94 | I13: 2 | J13: 16016 | M13: 72308 | N13: 99436
C14: 9 | D14: 60 | E14: female | F14: no | G14: northwest | H14: 8.61 | I14: 0 | J14: 72308 | M14: 6803 | N14: 120433
C15: 10 | D15: 25 | E15: male | F15: no | G15: northeast | H15: 8.74 | I15: 0 | J15: 6803 | M15: 4567 | N15: 96773
C16: 11 | D16: 62 | E16: female | F16: yes | G16: southeast | H16: 8.76 | I16: 0 | J16: 69522 | M16: 27727 | N16: 58921
... C278: 273 | D278: 50 | E278: male | F278: no | G278: northeast | H278: 9.15 | I278: 1 | J278: 24044 | M278: 35333 | N278: 72853
C279: 274 | D279: 25 | E279: male | F279: no | G279: northwest | H279: 9.18 | I279: 0 | J279: 6308 | M279: 61508
C280: 275 | D280: 47 | E280: female | F280: no | G280: northeast | H280: 8.87 | I280: 2 | J280: 24290 | M280: 22360
C281: 276 | D281: 19 | E281: male | F281: no | G281: northwest | H281: 6.87 | I281: 2 | J281: 7009 | M281: 24051
C282: 277 | D282: 22 | E282: female | F282: no | G282: southwest | H282: 8.1 | I282: 0 | J282: 5376 | M282: 4593
C283: 278 | D283: 59 | E283: male | F283: no | G283: southeast | H283: 10.6 | I283: 2 | J283: 32322 | M283: 4019
C284: 279 | D284: 51 | E284: female | F284: no | G284: southeast | H284: 7.19 | I284: 1 | J284: 24638 | M284: 25108
C285: 280 | D285: 40 | E285: female | F285: yes | G285: northeast | H285: 9.37 | I285: 1 | J285: 55829 | M285: 11878
C286: 281 | D286: 54 | E286: male | F286: yes | G286: northeast | H286: 13.52 | I286: 3 | J286: 121373 | M286: 6494
C287: 282 | D287: 30 | E287: male | F287: no | G287: northeast | H287: 9.22 | I287: 1 | J287: 10593 | M287: 7951
C288: 283 | D288: 55 | E288: female | F288: no | G288: northeast | H288: 10.8 | I288: 1 | J288: 29698 | M288: 24446
C289: 284 | D289: 52 | E289: female | F289: no | G289: southwest | H289: 10.4 | I289: 0 | J289: 24065 | M289: 33576
C290: 285 | D290: 46 | E290: male | F290: no | G290: southeast | H290: 8.87 | I290: 1 | J290: 19355 | M290: 20043
... C1068: 1063 | D1068: 36 | E1068: male | F1068: no | G1068: northwest | H1068: 9.53 | I1068: 3 | J1068: 16370 | M1068: 5020
C1069: 1064 | D1069: 29 | E1069: female | F1069: no | G1069: southwest | H1069: 8.53 | I1069: 4 | J1069: 14272
C1070: 1065 | D1070: 42 | E1070: female | F1070: no | G1070: southwest | H1070: 8.43 | I1070: 1 | J1070: 17614
C1071: 1066 | D1071: 48 | E1071: male | F1071: no | G1071: southeast | H1071: 12.43 | I1071: 2 | J1071: 22445
C1072: 1067 | D1072: 39 | E1072: male | F1072: no | G1072: northeast | H1072: 14.22 | I1072: 0 | J1072: 14394
C1073: 1068 | D1073: 63 | E1073: male | F1073: no | G1073: northwest | H1073: 7.22 | I1073: 1 | J1073: 35875
C1074: 1069 | D1074: 54 | E1074: female | F1074: no | G1074: southeast | H1074: 10.63 | I1074: 1 | J1074: 27322
C1075: 1070 | D1075: 37 | E1075: male | F1075: yes | G1075: southeast | H1075: 12.36 | I1075: 1 | J1075: 99679
C1076: 1071 | D1076: 63 | E1076: male | F1076: no | G1076: northeast | H1076: 10.48 | I1076: 0 | J1076: 34936
C1077: 1072 | D1077: 21 | E1077: male | F1077: no | G1077: northwest | H1077: 10.42 | I1077: 0 | J1077: 4774
C1078: 1073 | D1078: 54 | E1078: female | F1078: no | G1078: northeast | H1078: 9.63 | I1078: 2 | J1078: 30242
...
